Traceback (most recent call last):
  File "/home/cough052/shared/anaconda3/envs/nmma/lib/python3.7/site-packages/pandas/core/indexes/base.py", line 3361, in get_loc
    return self._engine.get_loc(casted_key)
  File "pandas/_libs/index.pyx", line 76, in pandas._libs.index.IndexEngine.get_loc
  File "pandas/_libs/index.pyx", line 108, in pandas._libs.index.IndexEngine.get_loc
  File "pandas/_libs/hashtable_class_helper.pxi", line 5198, in pandas._libs.hashtable.PyObjectHashTable.get_item
  File "pandas/_libs/hashtable_class_helper.pxi", line 5206, in pandas._libs.hashtable.PyObjectHashTable.get_item
KeyError: 'jsonPath'

The above exception was the direct cause of the following exception:

Traceback (most recent call last):
  File "/panfs/roc/groups/7/cough052/barna314/nmma_fitter/stats.py", line 742, in <module>
    df = get_dataframe(candDir=args.candDir, models=args.models, save=True)
  File "/panfs/roc/groups/7/cough052/barna314/nmma_fitter/stats.py", line 238, in get_dataframe
    df['jsonPath'] = df['jsonPath'].astype('str')
  File "/home/cough052/shared/anaconda3/envs/nmma/lib/python3.7/site-packages/pandas/core/frame.py", line 3455, in __getitem__
    indexer = self.columns.get_loc(key)
  File "/home/cough052/shared/anaconda3/envs/nmma/lib/python3.7/site-packages/pandas/core/indexes/base.py", line 3363, in get_loc
    raise KeyError(key) from err
KeyError: 'jsonPath'
